<?xml version="1.0"?>
<robot name="arm_robot">

  <!-- Origin of Gazebo world -->
  <link name="world"/>

  <!--Combine "base_link" with "world" ("base_link is fiexd on the world) -->
  <joint name="base_joint" type="fixed">
    <parent link="world"/>
    <child link="base_link"/>
  </joint>

  <!-- Create base link -->
  <link name="base_link">
    <inertial>
      <!-- rpy: roll, pitch, yaw -->
      <origin xyz="0 0 0.5" rpy="0 0 0"/>
      <mass value="1.0"/>
      <inertia ixx="1.0" ixy="0.0" ixz="0.0" iyy="0.0" iyz="0.0" izz="1.0"/>
    </inertial>
    <visual>
      <origin xyz="0 0 0.5" rpy="0 0 0"/>
      <geometry>
        <box size="0.1 0.1 1.0"/>
      </geometry>
    </visual>
    <collision>
      <origin xyz="0 0 0.5" rpy="0 0 0"/>
      <geometry>
        <box size="0.1 0.1 1.0"/>
      </geometry>
    </collision>
  </link>
  <gazebo reference="base_link">
    <material>Gazebo/Red</material>
  </gazebo>

  <!-- Create moving link -->
  <link name="arm1_link">
    <inertial>
      <mass value="1.0"/>
      <origin xyz="0 0 0.25" rpy="0 0 0"/>
      <inertia ixx="1.0" ixy="0.0" ixz="0.0" iyy="1.0" iyz="0.0" izz="1.0"/>
    </inertial>
    <visual>
      <origin xyz="0 0 0.25" rpy="0 0 0"/>
      <geometry>
        <box size="0.1 0.1 0.5"/>
      </geometry>
    </visual>
    <collision>
      <origin xyz="0 0 0.25" rpy="0 0 0"/>
      <geometry>
        <box size="0.1 0.1 0.5"/>
      </geometry>
    </collision>
  </link>
  <gazebo reference="arm1_link">
    <material>Gazebo/Blue</material>
  </gazebo>

  <!-- Create jonit to combine "base_link" with "arm1_link" -->
  <joint name="arm1_joint" type="continuous">
    <parent link="base_link"/>
    <child link="arm1_link"/>
    <axis xyz="0 1 0"/>
    <origin xyz="0 0.1 1.0" rpy="0 0 0"/>
    <dynamics damping="0.1"/>
  </joint>

  <!-- Create transmission to move "arm1_link" -->
  <transmission name="arm1_trans">
    <type>transmission_interface/SimpleTransimssion</type>
    <!-- Set joint name and H/W interface to control -->
    <joint name="arm1_joint">
      <!-- Interfaces except for "EffortJoinInterface" are not supported -->
      <hardwareInterface>hardware_interface/EffortJointInterface</hardwareInterface>
    </joint>
    <!-- Basically use "EffortJointInterface" -->
    <actuator name="arm1_motor">
      <hardwareInterface>hardware_interface/EffortJointInterface</hardwareInterface>
      <mechanismReduction>1</mechanismReduction>
    </actuator>
  </transmission>

  <gazebo>
    <!-- Load "ROS control" -->
    <plugin name="gazebo_ros_control" filename="libgazebo_ros_control.so">
      <!-- Set the same name of robot name in line 2 -->
      <robotNamespace>/arm_robot</robotNamespace>
      <!-- An error occurs without this tag -->
      <legacyModeNS>ture</legacyModeNS>
    </plugin>
  </gazebo>
</robot>
